2019-02-26 19:39:55,746 - ERROR - sql_util.py#connect_mysql():48 - main - Traceback (most recent call last):
  File "/Library/anaconda3/envs/mysql/lib/python3.6/site-packages/pymysql/connections.py", line 583, in connect
    **kwargs)
  File "/Library/anaconda3/envs/mysql/lib/python3.6/socket.py", line 722, in create_connection
    raise err
  File "/Library/anaconda3/envs/mysql/lib/python3.6/socket.py", line 713, in create_connection
    sock.connect(sa)
TimeoutError: [Errno 60] Operation timed out

During handling of the above exception, another exception occurred:

Traceback (most recent call last):
  File "/home/workspace/python/process_news/utils/sql_util.py", line 46, in connect_mysql
    return pymysql.connect(cursorclass=pymysql.cursors.DictCursor, **load_dict)
  File "/Library/anaconda3/envs/mysql/lib/python3.6/site-packages/pymysql/__init__.py", line 94, in Connect
    return Connection(*args, **kwargs)
  File "/Library/anaconda3/envs/mysql/lib/python3.6/site-packages/pymysql/connections.py", line 325, in __init__
    self.connect()
  File "/Library/anaconda3/envs/mysql/lib/python3.6/site-packages/pymysql/connections.py", line 630, in connect
    raise exc
pymysql.err.OperationalError: (2003, "Can't connect to MySQL server on '112.74.36.53' ([Errno 60] Operation timed out)")

2019-02-26 19:39:55,748 - ERROR - sql_util.py#connect_mysql():49 - main - cannot create mysql connect
2019-02-26 19:49:33,361 - ERROR - sql_util.py#connect_mysql():48 - main - Traceback (most recent call last):
  File "/Library/anaconda3/envs/mysql/lib/python3.6/site-packages/pymysql/connections.py", line 583, in connect
    **kwargs)
  File "/Library/anaconda3/envs/mysql/lib/python3.6/socket.py", line 722, in create_connection
    raise err
  File "/Library/anaconda3/envs/mysql/lib/python3.6/socket.py", line 713, in create_connection
    sock.connect(sa)
TimeoutError: [Errno 60] Operation timed out

During handling of the above exception, another exception occurred:

Traceback (most recent call last):
  File "/home/workspace/python/process_news/utils/sql_util.py", line 46, in connect_mysql
    return pymysql.connect(cursorclass=pymysql.cursors.DictCursor, **load_dict)
  File "/Library/anaconda3/envs/mysql/lib/python3.6/site-packages/pymysql/__init__.py", line 94, in Connect
    return Connection(*args, **kwargs)
  File "/Library/anaconda3/envs/mysql/lib/python3.6/site-packages/pymysql/connections.py", line 325, in __init__
    self.connect()
  File "/Library/anaconda3/envs/mysql/lib/python3.6/site-packages/pymysql/connections.py", line 630, in connect
    raise exc
pymysql.err.OperationalError: (2003, "Can't connect to MySQL server on '112.74.36.53' ([Errno 60] Operation timed out)")

2019-02-26 19:49:33,362 - ERROR - sql_util.py#connect_mysql():49 - main - cannot create mysql connect
2019-02-26 20:25:03,418 - ERROR - sql_util.py#connect_mysql():48 - main - Traceback (most recent call last):
  File "/Library/anaconda3/envs/mysql/lib/python3.6/site-packages/pymysql/connections.py", line 583, in connect
    **kwargs)
  File "/Library/anaconda3/envs/mysql/lib/python3.6/socket.py", line 722, in create_connection
    raise err
  File "/Library/anaconda3/envs/mysql/lib/python3.6/socket.py", line 713, in create_connection
    sock.connect(sa)
socket.timeout: timed out

During handling of the above exception, another exception occurred:

Traceback (most recent call last):
  File "/home/workspace/python/process_news/utils/sql_util.py", line 46, in connect_mysql
    return pymysql.connect(cursorclass=pymysql.cursors.DictCursor, **load_dict)
  File "/Library/anaconda3/envs/mysql/lib/python3.6/site-packages/pymysql/__init__.py", line 94, in Connect
    return Connection(*args, **kwargs)
  File "/Library/anaconda3/envs/mysql/lib/python3.6/site-packages/pymysql/connections.py", line 325, in __init__
    self.connect()
  File "/Library/anaconda3/envs/mysql/lib/python3.6/site-packages/pymysql/connections.py", line 630, in connect
    raise exc
pymysql.err.OperationalError: (2003, "Can't connect to MySQL server on '112.74.36.53' (timed out)")

2019-02-26 20:25:03,418 - ERROR - sql_util.py#connect_mysql():49 - main - cannot create mysql connect
2019-02-26 20:30:18,625 - ERROR - sql_util.py#connect_mysql():48 - main - Traceback (most recent call last):
  File "/Library/anaconda3/envs/mysql/lib/python3.6/site-packages/pymysql/connections.py", line 583, in connect
    **kwargs)
  File "/Library/anaconda3/envs/mysql/lib/python3.6/socket.py", line 722, in create_connection
    raise err
  File "/Library/anaconda3/envs/mysql/lib/python3.6/socket.py", line 713, in create_connection
    sock.connect(sa)
TimeoutError: [Errno 60] Operation timed out

During handling of the above exception, another exception occurred:

Traceback (most recent call last):
  File "/home/workspace/python/process_news/utils/sql_util.py", line 46, in connect_mysql
    return pymysql.connect(cursorclass=pymysql.cursors.DictCursor, **load_dict)
  File "/Library/anaconda3/envs/mysql/lib/python3.6/site-packages/pymysql/__init__.py", line 94, in Connect
    return Connection(*args, **kwargs)
  File "/Library/anaconda3/envs/mysql/lib/python3.6/site-packages/pymysql/connections.py", line 325, in __init__
    self.connect()
  File "/Library/anaconda3/envs/mysql/lib/python3.6/site-packages/pymysql/connections.py", line 630, in connect
    raise exc
pymysql.err.OperationalError: (2003, "Can't connect to MySQL server on '112.74.36.53' ([Errno 60] Operation timed out)")

2019-02-26 20:30:18,626 - ERROR - sql_util.py#connect_mysql():49 - main - cannot create mysql connect
